Workbook
Name neighbourhood_crime_rates___4326: Raw!$A$1:$HM$159

Sheet Cleaned
B1: 2014 | C1: 2015 | D1: 2016 | E1: 2017 | F1: 2018 | G1: 2019 | H1: 2020 | I1: 2021 | J1: 2022 | K1: 2023 | L1: 2024 | M1: 2025
A2: Assault | B2: =AVERAGE(Raw!P2:P159) -> 610.44511 | C2: =AVERAGE(Raw!Q2:Q159) -> 657.35087 | D2: =AVERAGE(Raw!R2:R159) -> 657.29193 | E2: =AVERAGE(Raw!S2:S159) -> 660.61759 | F2: =AVERAGE(Raw!T2:T159) -> 666.58272 | G2: =AVERAGE(Raw!U2:U159) -> 695.51506 | H2: =AVERAGE(Raw!V2:V159) -> 597.53512 | I2: =AVERAGE(Raw!W2:W159) -> 630.52788 | ... M2: =AVERAGE(Raw!AA2:AA159) -> 745.49526
A3: Auto Theft | B3: =AVERAGE(Raw!AN2:AN159) -> 125.78208 | C3: =AVERAGE(Raw!AO2:AO159) -> 119.8587 | D3: =AVERAGE(Raw!AP2:AP159) -> 116.48943 | E3: =AVERAGE(Raw!AQ2:AQ159) -> 124.88173 | F3: =AVERAGE(Raw!AR2:AR159) -> 161.10382 | G3: =AVERAGE(Raw!AS2:AS159) -> 174.59882 | H3: =AVERAGE(Raw!AT2:AT159) -> 190.38375 | I3: =AVERAGE(Raw!AU2:AU159) -> 220.39432 | ... M3: =AVERAGE(Raw!AY2:AY159) -> 216.51482
A4: Theft over $5k | B4: =AVERAGE(Raw!GZ2:GZ159) -> 37.410538 | C4: =AVERAGE(Raw!HA2:HA159) -> 37.057743 | D4: =AVERAGE(Raw!HB2:HB159) -> 38.112012 | E4: =AVERAGE(Raw!HC2:HC159) -> 40.286497 | F4: =AVERAGE(Raw!HD2:HD159) -> 42.146618 | G4: =AVERAGE(Raw!HE2:HE159) -> 46.314849 | H4: =AVERAGE(Raw!HF2:HF159) -> 40.732553 | I4: =AVERAGE(Raw!HG2:HG159) -> 35.952109 | ... M4: =AVERAGE(Raw!HK2:HK159) -> 56.83065
A5: Bike Theft | B5: =AVERAGE(Raw!BL2:BL159) -> 132.67899 | C5: =AVERAGE(Raw!BM2:BM159) -> 134.33203 | D5: =AVERAGE(Raw!BN2:BN159) -> 148.27381 | E5: =AVERAGE(Raw!BO2:BO159) -> 149.35539 | F5: =AVERAGE(Raw!BP2:BP159) -> 152.52611 | G5: =AVERAGE(Raw!BQ2:BQ159) -> 136.76621 | H5: =AVERAGE(Raw!BR2:BR159) -> 148.36868 | I5: =AVERAGE(Raw!BS2:BS159) -> 117.76099 | ... M5: =AVERAGE(Raw!BW2:BW159) -> 69.111893
A6: Robbery | B6: =AVERAGE(Raw!EF2:EF159) -> 137.85303 | C6: =AVERAGE(Raw!EG2:EG159) -> 125.31555 | D6: =AVERAGE(Raw!EH2:EH159) -> 129.64032 | E6: =AVERAGE(Raw!EI2:EI159) -> 138.8149 | F6: =AVERAGE(Raw!EJ2:EJ159) -> 126.40068 | G6: =AVERAGE(Raw!EK2:EK159) -> 118.85957 | H6: =AVERAGE(Raw!EL2:EL159) -> 91.36881 | I6: =AVERAGE(Raw!EM2:EM159) -> 75.047368 | ... M6: =AVERAGE(Raw!EQ2:EQ159) -> 76.398116
A7: Theft from Vehicle | B7: =AVERAGE(Raw!GB2:GB159) -> 353.3955 | C7: =AVERAGE(Raw!GC2:GC159) -> 319.8723 | D7: =AVERAGE(Raw!GD2:GD159) -> 271.29642 | E7: =AVERAGE(Raw!GE2:GE159) -> 288.04463 | F7: =AVERAGE(Raw!GF2:GF159) -> 306.7304 | G7: =AVERAGE(Raw!GG2:GG159) -> 335.38718 | H7: =AVERAGE(Raw!GH2:GH159) -> 343.76395 | I7: =AVERAGE(Raw!GI2:GI159) -> 269.57443 | ... M7: =AVERAGE(Raw!GM2:GM159) -> 207.86162
A8: Break & Enter | B8: =AVERAGE(Raw!CJ2:CJ159) -> 268.16452 | C8: =AVERAGE(Raw!CK2:CK159) -> 255.71972 | D8: =AVERAGE(Raw!CL2:CL159) -> 229.89643 | E8: =AVERAGE(Raw!CM2:CM159) -> 243.42736 | F8: =AVERAGE(Raw!CN2:CN159) -> 260.22554 | G8: =AVERAGE(Raw!CO2:CO159) -> 289.70308 | H8: =AVERAGE(Raw!CP2:CP159) -> 239.44938 | I8: =AVERAGE(Raw!CQ2:CQ159) -> 191.50056 | ... M8: =AVERAGE(Raw!CU2:CU159) -> 189.86341
A10: index to 2014 | B10: 2014 | C10: 2015 | D10: 2016 | E10: 2017 | F10: 2018 | G10: 2019 | H10: 2020 | I10: 2021 | J10: 2022 | K10: 2023 | L10: 2024 | M10: 2025
A11: Assault | B11: =B2/$B2*100 -> 100 | C11: =C2/$B2*100 -> 107.68386 | D11: =D2/$B2*100 -> 107.67421 | E11: =E2/$B2*100 -> 108.219 | F11: =F2/$B2*100 -> 109.19618 | G11: =G2/$B2*100 -> 113.93572 | H11: =H2/$B2*100 -> 97.885151 | I11: =I2/$B2*100 -> 103.28986 | ... M11: =M2/$B2*100 -> 122.12323
A12: Auto Theft | B12: =B3/$B3*100 -> 100 | C12: =C3/$B3*100 -> 95.290755 | D12: =D3/$B3*100 -> 92.612102 | E12: =E3/$B3*100 -> 99.284195 | F12: =F3/$B3*100 -> 128.08169 | G12: =G3/$B3*100 -> 138.81057 | H12: =H3/$B3*100 -> 151.35999 | I12: =I3/$B3*100 -> 175.21917 | ... M12: =M3/$B3*100 -> 172.13487
A13: Theft over $5k | B13: =B4/$B4*100 -> 100 | C13: =C4/$B4*100 -> 99.056962 | D13: =D4/$B4*100 -> 101.87507 | E13: =E4/$B4*100 -> 107.68756 | F13: =F4/$B4*100 -> 112.65975 | G13: =G4/$B4*100 -> 123.80161 | H13: =H4/$B4*100 -> 108.87989 | I13: =I4/$B4*100 -> 96.101554 | ... M13: =M4/$B4*100 -> 151.9108
A14: Bike Theft | B14: =B5/$B5*100 -> 100 | C14: =C5/$B5*100 -> 101.24589 | D14: =D5/$B5*100 -> 111.7538 | E14: =E5/$B5*100 -> 112.56899 | F14: =F5/$B5*100 -> 114.95875 | G14: =G5/$B5*100 -> 103.08053 | H14: =H5/$B5*100 -> 111.8253 | I14: =I5/$B5*100 -> 88.756326 | ... M14: =M5/$B5*100 -> 52.089554
A15: Robbery | B15: =B6/$B6*100 -> 100 | C15: =C6/$B6*100 -> 90.905179 | D15: =D6/$B6*100 -> 94.042415 | E15: =E6/$B6*100 -> 100.69775 | F15: =F6/$B6*100 -> 91.692347 | G15: =G6/$B6*100 -> 86.221946 | H15: =H6/$B6*100 -> 66.279869 | I15: =I6/$B6*100 -> 54.440128 | ... M15: =M6/$B6*100 -> 55.419974
A16: Theft from Vehicle | B16: =B7/$B7*100 -> 100 | C16: =C7/$B7*100 -> 90.513971 | D16: =D7/$B7*100 -> 76.768499 | E16: =E7/$B7*100 -> 81.507723 | F16: =F7/$B7*100 -> 86.795217 | G16: =G7/$B7*100 -> 94.9042 | H16: =H7/$B7*100 -> 97.274569 | I16: =I7/$B7*100 -> 76.281229 | ... M16: =M7/$B7*100 -> 58.818411
A17: Break & Enter | B17: =B8/$B8*100 -> 100 | C17: =C8/$B8*100 -> 95.359268 | D17: =D8/$B8*100 -> 85.729624 | E17: =E8/$B8*100 -> 90.775379 | F17: =F8/$B8*100 -> 97.039513 | G17: =G8/$B8*100 -> 108.03185 | H17: =H8/$B8*100 -> 89.291968 | I17: =I8/$B8*100 -> 71.411594 | ... M17: =M8/$B8*100 -> 70.801093

Sheet Raw
A1: _id | B1: AREA_NAME | C1: HOOD_ID | D1: ASSAULT_2014 | E1: ASSAULT_2015 | F1: ASSAULT_2016 | G1: ASSAULT_2017 | H1: ASSAULT_2018 | I1: ASSAULT_2019 | J1: ASSAULT_2020 | K1: ASSAULT_2021 | L1: ASSAULT_2022 | M1: ASSAULT_2023 | N1: ASSAULT_2024 | O1: ASSAULT_2025 | P1: ASSAULT_RATE_2014 | Q1: ASSAULT_RATE_2015 | R1: ASSAULT_RATE_2016 | S1: ASSAULT_RATE_2017 | T1: ASSAULT_RATE_2018 | U1: ASSAULT_RATE_2019 | V1: ASSAULT_RATE_2020 | W1: ASSAULT_RATE_2021 | X1: ASSAULT_RATE_2022 | Y1: ASSAULT_RATE_2023 | Z1: ASSAULT_RATE_2024 | AA1: ASSAULT_RATE_2025 | AB1: AUTOTHEFT_2014 | AC1: AUTOTHEFT_2015 | AD1: AUTOTHEFT_2016 | AE1: AUTOTHEFT_2017 | AF1: AUTOTHEFT_2018 | AG1: AUTOTHEFT_2019 | AH1: AUTOTHEFT_2020 | AI1: AUTOTHEFT_2021 | AJ1: AUTOTHEFT_2022 | AK1: AUTOTHEFT_2023 | AL1: AUTOTHEFT_2024 | AM1: AUTOTHEFT_2025 | AN1: AUTOTHEFT_RATE_2014 | AO1: AUTOTHEFT_RATE_2015 | AP1: AUTOTHEFT_RATE_2016 | AQ1: AUTOTHEFT_RATE_2017 | AR1: AUTOTHEFT_RATE_2018 | AS1: AUTOTHEFT_RATE_2019 | AT1: AUTOTHEFT_RATE_2020 | AU1: AUTOTHEFT_RATE_2021 | AV1: AUTOTHEFT_RATE_2022 | AW1: AUTOTHEFT_RATE_2023 | AX1: AUTOTHEFT_RATE_2024 | AY1: AUTOTHEFT_RATE_2025 | AZ1: BIKETHEFT_2014 | BA1: BIKETHEFT_2015 | BB1: BIKETHEFT_2016 | BC1: BIKETHEFT_2017 | BD1: BIKETHEFT_2018 | BE1: BIKETHEFT_2019 | BF1: BIKETHEFT_2020 | BG1: BIKETHEFT_2021 | BH1: BIKETHEFT_2022 | BI1: BIKETHEFT_2023 | BJ1: BIKETHEFT_2024 | BK1: BIKETHEFT_2025 | BL1: BIKETHEFT_RATE_2014 | BM1: BIKETHEFT_RATE_2015 | BN1: BIKETHEFT_RATE_2016 | BO1: BIKETHEFT_RATE_2017 | BP1: BIKETHEFT_RATE_2018 | BQ1: BIKETHEFT_RATE_2019 | BR1: BIKETHEFT_RATE_2020 | BS1: BIKETHEFT_RATE_2021 | BT1: BIKETHEFT_RATE_2022 | BU1: BIKETHEFT_RATE_2023 | BV1: BIKETHEFT_RATE_2024 | BW1: BIKETHEFT_RATE_2025 | BX1: BREAKENTER_2014 | BY1: BREAKENTER_2015 | BZ1: BREAKENTER_2016 | CA1: BREAKENTER_2017 | CB1: BREAKENTER_2018 | CC1: BREAKENTER_2019 | CD1: BREAKENTER_2020 | CE1: BREAKENTER_2021 | CF1: BREAKENTER_2022 | CG1: BREAKENTER_2023 | CH1: BREAKENTER_2024 | CI1: BREAKENTER_2025 | CJ1: BREAKENTER_RATE_2014 | CK1: BREAKENTER_RATE_2015 | CL1: BREAKENTER_RATE_2016 | CM1: BREAKENTER_RATE_2017 | CN1: BREAKENTER_RATE_2018 | CO1: BREAKENTER_RATE_2019 | CP1: BREAKENTER_RATE_2020 | CQ1: BREAKENTER_RATE_2021 | CR1: BREAKENTER_RATE_2022 | CS1: BREAKENTER_RATE_2023 | CT1: BREAKENTER_RATE_2024 | CU1: BREAKENTER_RATE_2025 | CV1: HOMICIDE_2014 | CW1: HOMICIDE_2015 | CX1: HOMICIDE_2016 | CY1: HOMICIDE_2017 | CZ1: HOMICIDE_2018 | DA1: HOMICIDE_2019 | DB1: HOMICIDE_2020 | DC1: HOMICIDE_2021 | DD1: HOMICIDE_2022 | DE1: HOMICIDE_2023 | DF1: HOMICIDE_2024 | DG1: HOMICIDE_2025 | DH1: HOMICIDE_RATE_2014 | DI1: HOMICIDE_RATE_2015 | DJ1: HOMICIDE_RATE_2016 | DK1: HOMICIDE_RATE_2017 | DL1: HOMICIDE_RATE_2018 | DM1: HOMICIDE_RATE_2019 | DN1: HOMICIDE_RATE_2020 | DO1: HOMICIDE_RATE_2021 | DP1: HOMICIDE_RATE_2022 | DQ1: HOMICIDE_RATE_2023 | DR1: HOMICIDE_RATE_2024 | DS1: HOMICIDE_RATE_2025 | DT1: ROBBERY_2014 | DU1: ROBBERY_2015 | DV1: ROBBERY_2016 | DW1: ROBBERY_2017 | DX1: ROBBERY_2018 | DY1: ROBBERY_2019 | DZ1: ROBBERY_2020 | EA1: ROBBERY_2021 | EB1: ROBBERY_2022 | EC1: ROBBERY_2023 | ED1: ROBBERY_2024 | EE1: ROBBERY_2025 | EF1: ROBBERY_RATE_2014 | EG1: ROBBERY_RATE_2015 | EH1: ROBBERY_RATE_2016 | EI1: ROBBERY_RATE_2017 | EJ1: ROBBERY_RATE_2018 | EK1: ROBBERY_RATE_2019 | EL1: ROBBERY_RATE_2020 | EM1: ROBBERY_RATE_2021 | EN1: ROBBERY_RATE_2022 | EO1: ROBBERY_RATE_2023 | EP1: ROBBERY_RATE_2024 | EQ1: ROBBERY_RATE_2025 | ER1: SHOOTING_2014 | ES1: SHOOTING_2015 | ET1: SHOOTING_2016 | EU1: SHOOTING_2017 | EV1: SHOOTING_2018 | EW1: SHOOTING_2019 | EX1: SHOOTING_2020 | EY1: SHOOTING_2021 | EZ1: SHOOTING_2022 | FA1: SHOOTING_2023 | FB1: SHOOTING_2024 | FC1: SHOOTING_2025 | FD1: SHOOTING_RATE_2014 | FE1: SHOOTING_RATE_2015 | FF1: SHOOTING_RATE_2016 | FG1: SHOOTING_RATE_2017 | FH1: SHOOTING_RATE_2018 | FI1: SHOOTING_RATE_2019 | FJ1: SHOOTING_RATE_2020 | FK1: SHOOTING_RATE_2021 | FL1: SHOOTING_RATE_2022 | FM1: SHOOTING_RATE_2023 | FN1: SHOOTING_RATE_2024 | FO1: SHOOTING_RATE_2025 | FP1: THEFTFROMMV_2014 | FQ1: THEFTFROMMV_2015 | FR1: THEFTFROMMV_2016 | FS1: THEFTFROMMV_2017 | FT1: THEFTFROMMV_2018 | FU1: THEFTFROMMV_2019 | FV1: THEFTFROMMV_2020 | FW1: THEFTFROMMV_2021 | FX1: THEFTFROMMV_2022 | FY1: THEFTFROMMV_2023 | FZ1: THEFTFROMMV_2024 | GA1: THEFTFROMMV_2025 | GB1: THEFTFROMMV_RATE_2014 | GC1: THEFTFROMMV_RATE_2015 | GD1: THEFTFROMMV_RATE_2016 | GE1: THEFTFROMMV_RATE_2017 | GF1: THEFTFROMMV_RATE_2018 | GG1: THEFTFROMMV_RATE_2019 | GH1: THEFTFROMMV_RATE_2020 | GI1: THEFTFROMMV_RATE_2021 | GJ1: THEFTFROMMV_RATE_2022 | GK1: THEFTFROMMV_RATE_2023 | GL1: THEFTFROMMV_RATE_2024 | GM1: THEFTFROMMV_RATE_2025 | GN1: THEFTOVER_2014 | GO1: THEFTOVER_2015 | GP1: THEFTOVER_2016 | GQ1: THEFTOVER_2017 | GR1: THEFTOVER_2018 | GS1: THEFTOVER_2019 | GT1: THEFTOVER_2020 | GU1: THEFTOVER_2021 | GV1: THEFTOVER_2022 | GW1: THEFTOVER_2023 | GX1: THEFTOVER_2024 | GY1: THEFTOVER_2025 | GZ1: THEFTOVER_RATE_2014 | HA1: THEFTOVER_RATE_2015 | HB1: THEFTOVER_RATE_2016 | HC1: THEFTOVER_RATE_2017 | HD1: THEFTOVER_RATE_2018 | HE1: THEFTOVER_RATE_2019 | HF1: THEFTOVER_RATE_2020 | HG1: THEFTOVER_RATE_2021 | HH1: THEFTOVER_RATE_2022 | HI1: THEFTOVER_RATE_2023 | HJ1: THEFTOVER_RATE_2024 | HK1: THEFTOVER_RATE_2025 | HL1: POPULATION_2025 | HM1: geometry
A2: 1 | B2: South Eglinton-Davisville | C2: 174 | D2: 55 | E2: 56 | F2: 66 | G2: 73 | H2: 74 | I2: 62 | J2: 74 | K2: 106 | L2: 122 | M2: 100 | N2: 123 | O2: 126 | P2: 301.17184 | Q2: 304.91125 | R2: 342.82153 | S2: 356.34091 | T2: 340.33942 | U2: 270.68326 | V2: 309.70117 | W2: 427.83337 | X2: 474.39438 | Y2: 368.74515 | Z2: 434.36804 | AA2: 435.95599 | AB2: 2 | AC2: 4 | AD2: 8 | AE2: 7 | AF2: 14 | AG2: 8 | AH2: 15 | AI2: 16 | AJ2: 10 | AK2: 20 | AL2: 19 | AM2: 17 | AN2: 10.951703 | AO2: 21.779375 | AP2: 41.554123 | AQ2: 34.169678 | AR2: 64.388542 | AS2: 34.926872 | AT2: 62.777267 | AU2: 64.578621 | AV2: 38.884785 | AW2: 73.749031 | AX2: 67.097504 | AY2: 58.819458 | AZ2: 14 | BA2: 19 | BB2: 27 | BC2: 33 | BD2: 29 | BE2: 42 | BF2: 92 | BG2: 33 | BH2: 16 | BI2: 37 | BJ2: 21 | BK2: 6 | BL2: 76.661919 | BM2: 103.45203 | BN2: 140.24516 | BO2: 161.08562 | BP2: 133.37627 | BQ2: 183.36607 | BR2: 385.03391 | BS2: 133.19342 | BT2: 62.215656 | BU2: 136.43571 | BV2: 74.1604 | BW2: 20.759809 | BX2: 27 | BY2: 32 | BZ2: 25 | CA2: 37 | CB2: 48 | CC2: 83 | CD2: 69 | CE2: 44 | CF2: 24 | CG2: 43 | CH2: 52 | CI2: 37 | CJ2: 147.84799 | CK2: 174.235 | CL2: 129.85664 | CM2: 180.61115 | CN2: 220.76071 | CO2: 362.3663 | CP2: 288.77542 | CQ2: 177.59122 | CR2: 93.323486 | CS2: 158.56042 | CT2: 183.63527 | CU2: 128.01883 | CX2: 1 | DA2: 1 | DB2: 1 | DC2: 1 | DJ2: 5.1942654 | DM2: 4.365859 | DN2: 4.1851511 | DO2: 4.0361638 | DT2: 10 | DU2: 8 | DV2: 8 | DW2: 7 | DX2: 12 | DY2: 5 | DZ2: 16 | EA2: 9 | EB2: 15 | EC2: 3 | ED2: 16 | EE2: 7 | EF2: 54.758514 | EG2: 43.55875 | EH2: 41.554123 | EI2: 34.169678 | EJ2: 55.190178 | EK2: 21.829294 | EL2: 66.962418 | EM2: 36.325478 | EN2: 58.327175 | EO2: 11.062355 | EP2: 56.503162 | EQ2: 24.219778 | ER2: 1 | ET2: 1 | EV2: 1 | EX2: 1 | EZ2: 1 | FB2: 2 | FD2: 5.4758515 | FF2: 5.1942654 | FH2: 4.5991812 | FJ2: 4.1851511 | FL2: 3.8884785 | FN2: 7.0628953 | FP2: 13 | FQ2: 18 | FR2: 11 | FS2: 16 | FT2: 18 | FU2: 24 | FV2: 41 | FW2: 22 | FX2: 42 | FY2: 40 | FZ2: 25 | GA2: 29 | GB2: 71.186066 | GC2: 98.007187 | GD2: 57.136921 | GE2: 78.102119 | GF2: 82.785263 | GG2: 104.78062 | GH2: 171.5912 | GI2: 88.795609 | GJ2: 163.3161 | GK2: 147.49806 | GL2: 88.286186 | GM2: 100.33907 | GN2: 4 | GO2: 3 | GP2: 4 | GQ2: 1 | GR2: 3 | GS2: 3 | GT2: 4 | GU2: 6 | GV2: 3 | GW2: 8 | GX2: 6 | GY2: 6 | GZ2: 21.903406 | HA2: 16.334532 | HB2: 20.777061 | HC2: 4.8813825 | HD2: 13.797544 | HE2: 13.097577 | HF2: 16.740604 | HG2: 24.216984 | HH2: 11.665436 | HI2: 29.499613 | HJ2: 21.188684 | HK2: 20.759809 | HL2: 28902 | HM2: {"coordinates": [[[[-79.3863542900264, 43.6978398552532], [-79.3862324335582, 43.6975123126537], [-79.3863913625999, 43.6975163231888], [-79.3864595384418, 43.697527848848], [-79.3866638782195, 43.6975096621283], [-79.3870142059089, 43.6974771361906], [-79.3876488180464, 43.6974063642873], [-79.38953145332, 43.696999773808], [-79.3927582054138, 43.6962910795871], [-79.395024336872, 43.6958490228948], [-79.3951317430406, 43.6958233235762], [-79.3952865919344, 43.6957885858324], [-79.3954645320225, 43.6957510688646], [-79.3955722517031, 43.6957309415535], [-79.3957195349856, 43.6957087170035], [-79.3958885287517, 43.6956939558398], [-79.3961113953839, 43.6956752022005], [-79.3962077513761, 43.6961356148857], [-79.3964742824193, 43.6973825270482], [-79.39664595586, 43.6983097965903], [-79.3968644530865, 43.6993406140572], [-79.39695718258, 43.6997952541724], [-79.3970424282089, 43.7003038763247], [-79.3971624772669, 43.7008620363003], [-79.3972224883211, 43.7011456123612], [-79.3973474098411, 43.7018027738763], [-79.3975086466549, 43.7025206442734], [-79.3976690471371, 43.7033016755171], [-79.3976874697869, 43.7034051989394], [-79.3978289167149, 43.7041568862326], [-79.3978557080699, 43.7043594211245], [-79.3982428954321, 43.7061529917479], [-79.3983697420418, 43.7067405816983], [-79.3974775703359, 43.7069304768233], [-79.3974398976879, 43.7069385089713], [-79.3968325305546, 43.7070677693265], [-79.3954958958023, 43.7073366109847], [-79.3941367573538, 43.7076099171548], [-79.3928226110264, 43.7078697477112], [-79.391504148294, 43.7081430508011], [-79.390200414339, 43.7084163448525], [-79.3892957551523, 43.7060932436803], [-79.3889371961999, 43.7051883123124], [-79.3885743459954, 43.7043013694656], [-79.3881601624623, 43.703301859302], [-79.3878348366839, 43.702477960142], [-79.387498266693, 43.7016540477108], [-79.3870343694937, 43.7005149638112], [-79.3869765700918, 43.7003213789767], [-79.3868375054959, 43.6998441918596], [-79.3867473981847, 43.6993085443841], [-79.3865336665207, 43.6983362118586], [-79.3864819981205, 43.6981831470634], [-79.3863542900264, 43.6978398552532]]]], "type": "MultiPolygon"}
A3: 2 | B3: North Toronto | C3: 173 | D3: 53 | E3: 57 | F3: 47 | G3: 61 | H3: 66 | I3: 84 | J3: 80 | K3: 118 | L3: 136 | M3: 105 | N3: 128 | O3: 129 | P3: 455.75717 | Q3: 492.31302 | R3: 406.39862 | S3: 482.21344 | T3: 477.53418 | U3: 561.76019 | V3: 501.28455 | W3: 700.50458 | X3: 766.36987 | Y3: 554.17743 | Z3: 640.16003 | AA3: 626.76123 | AB3: 8 | AC3: 2 | AD3: 2 | AE3: 2 | AF3: 3 | AG3: 5 | AH3: 14 | AI3: 15 | AJ3: 10 | AK3: 20 | AL3: 10 | AM3: 14 | AN3: 68.793533 | AO3: 17.274141 | AP3: 17.293558 | AQ3: 15.810277 | AR3: 21.706099 | AS3: 33.438107 | AT3: 87.724792 | AU3: 89.047195 | AV3: 56.350727 | AW3: 105.55761 | AX3: 50.012505 | AY3: 68.020599 | AZ3: 8 | BA3: 13 | BB3: 9 | BC3: 14 | BD3: 18 | BE3: 22 | BF3: 52 | BG3: 23 | BH3: 12 | BI3: 22 | BJ3: 14 | BK3: 15 | BL3: 68.793533 | BM3: 112.28191 | BN3: 77.821014 | BO3: 110.67194 | BP3: 130.2366 | BQ3: 147.12767 | BR3: 325.83496 | BS3: 136.53903 | BT3: 67.620872 | BU3: 116.11337 | BV3: 70.017502 | BW3: 72.879211 | BX3: 25 | BY3: 44 | BZ3: 15 | CA3: 24 | CB3: 42 | CC3: 36 | CD3: 89 | CE3: 49 | CF3: 48 | CG3: 31 | CH3: 31 | CI3: 36 | CJ3: 214.9798 | CK3: 380.0311 | CL3: 129.70169 | CM3: 189.72333 | CN3: 303.88541 | CO3: 240.75436 | CP3: 557.67908 | CQ3: 290.88751 | CR3: 270.48349 | CS3: 163.61429 | CT3: 155.03876 | CU3: 174.91011 | DA3: 1 | DB3: 1 | DM3: 6.6876211 | DN3: 6.2660565 | DT3: 7 | DU3: 12 | DV3: 8 | DW3: 6 | DX3: 14 | DY3: 19 | DZ3: 3 | EA3: 12 | EB3: 12 | EC3: 14 | ED3: 18 | EE3: 11 | EF3: 60.194344 | EG3: 103.64484 | EH3: 69.174232 | EI3: 47.430832 | EJ3: 101.29513 | EK3: 127.0648 | EL3: 18.79817 | EM3: 71.237755 | EN3: 67.620872 | EO3: 73.890327 | EP3: 90.022507 | EQ3: 53.444759 | EW3: 1 | EY3: 1 | EZ3: 1 | FB3: 1 | FI3: 6.6876211 | FK3: 5.9364796 | FL3: 5.6350727 | FN3: 5.0012503 | FP3: 23 | FQ3: 7 | FR3: 15 | FS3: 14 | FT3: 8 | FU3: 18 | FV3: 26 | FW3: 16 | FX3: 24 | FY3: 40 | FZ3: 11 | GA3: 13 | GB3: 197.7814 | GC3: 60.459492 | GD3: 129.70169 | GE3: 110.67194 | GF3: 57.882931 | GG3: 120.37718 | GH3: 162.91748 | GI3: 94.983673 | GJ3: 135.24174 | GK3: 211.11522 | GL3: 55.013752 | GM3: 63.161987 | GN3: 2 | GO3: 3 | GP3: 2 | GQ3: 2 | GR3: 5 | GS3: 4 | GT3: 7 | GU3: 2 | GV3: 4 | GW3: 7 | GX3: 6 | GY3: 5 | GZ3: 17.198383 | HA3: 25.911211 | HB3: 17.293558 | HC3: 15.810277 | HD3: 36.176834 | HE3: 26.750484 | HF3: 43.862396 | HG3: 11.872959 | HH3: 22.540291 | HI3: 36.945164 | HJ3: 30.007502 | HK3: 24.293072 | HL3: 20582 | HM3: {"coordinates": [[[[-79.3974398976879, 43.7069385089713], [-79.3983697420418, 43.7067405816983], [-79.3986310808226, 43.7079940611376], [-79.398681627227, 43.7082183179117], [-79.3988724581394, 43.7090963176949], [-79.3990006746799, 43.7095919421506], [-79.3992914701172, 43.710920903594], [-79.3993199098808, 43.7110852368503], [-79.3994798297642, 43.711847559868], [-79.399566439934, 43.712296943698], [-79.399372772142, 43.7123391241091], [-79.3989526732027, 43.7124163981867], [-79.3985914534404, 43.7124804825853], [-79.3978734488985, 43.7126268878588], [-79.395517942256, 43.7131171912401], [-79.3931238125479, 43.7136100203025], [-79.392203721203, 43.7137944115991], [-79.3917825020646, 43.7126146502055], [-79.3914609024979, 43.7117202850687], [-79.391230127098, 43.7111373418527], [-79.3906609194997, 43.7096241452835], [-79.390200414339, 43.7084163448525], [-79.391504148294, 43.7081430508011], [-79.3928226110264, 43.7078697477112], [-79.3941367573538, 43.7076099171548], [-79.3954958958023, 43.7073366109847], [-79.3968325305546, 43.7070677693265], [-79.3974398976879, 43.7069385089713]]]], "type": "MultiPolygon"}
A4: 3 | B4: Dovercourt Village | C4: 172 | D4: 62 | E4: 65 | F4: 92 | G4: 105 | H4: 106 | I4: 113 | J4: 91 | K4: 115 | L4: 103 | M4: 104 | N4: 118 | O4: 128 | P4: 456.15067 | Q4: 481.41016 | R4: 680.17151 | S4: 777.89301 | T4: 785.94202 | U4: 841.14935 | V4: 685.60236 | W4: 878.80176 | X4: 786.80011 | Y4: 783.84082 | Z4: 883.76276 | AA4: 974.94098 | AB4: 11 | AC4: 15 | AD4: 18 | AE4: 15 | AF4: 12 | AG4: 13 | AH4: 24 | AI4: 11 | AJ4: 25 | AK4: 29 | AL4: 36 | AM4: 17 | AN4: 80.929962 | AO4: 111.09465 | AP4: 133.07704 | AQ4: 111.12757 | AR4: 88.974571 | AS4: 96.769394 | AT4: 180.81821 | AU4: 84.059303 | AV4: 190.9709 | AW4: 218.571 | AX4: 269.62253 | AY4: 129.48434 | AZ4: 29 | BA4: 35 | BB4: 55 | BC4: 47 | BD4: 30 | BE4: 27 | BF4: 32 | BG4: 27 | BH4: 20 | BI4: 38 | BJ4: 34 | BK4: 23 | BL4: 213.36079 | BM4: 259.22086 | BN4: 406.62427 | BO4: 348.19974 | BP4: 222.43642 | BQ4: 200.98257 | BR4: 241.09094 | BS4: 206.32738 | BT4: 152.77672 | BU4: 286.40338 | BV4: 254.64349 | BW4: 175.18471 | BX4: 38 | BY4: 22 | BZ4: 38 | CA4: 39 | CB4: 50 | CC4: 83 | CD4: 47 | CE4: 19 | CF4: 33 | CG4: 46 | CH4: 45 | CI4: 31 | CJ4: 279.57623 | CK4: 162.93883 | CL4: 280.9404 | CM4: 288.9317 | CN4: 370.72736 | CO4: 617.83533 | CP4: 354.10233 | CQ4: 145.19333 | CR4: 252.08159 | CS4: 346.69882 | CT4: 337.02817 | CU4: 236.11852 | CV4: 1 | CY4: 1 | DA4: 2 | DB4: 1 | DH4: 7.3572688 | DK4: 7.408505 | DM4: 14.887599 | DN4: 7.5340919 | DT4: 29 | DU4: 27 | DV4: 16 | DW4: 42 | DX4: 35 | DY4: 17 | DZ4: 16 | EA4: 22 | EB4: 14 | EC4: 21 | ED4: 12 | EE4: 9 | EF4: 213.36079 | EG4: 199.97037 | EH4: 118.2907 | EI4: 311.1572 | EJ4: 259.50916 | EK4: 126.54459 | EL4: 120.54547 | EM4: 168.11861 | EN4: 106.9437 | EO4: 158.27554 | EP4: 89.874176 | EQ4: 68.550537 | ET4: 2 | EY4: 2 | FA4: 1 | FB4: 2 | FF4: 14.786338 | FK4: 15.283509 | FM4: 7.536931 | FN4: 14.97903 | FP4: 45 | FQ4: 38 | FR4: 51 | FS4: 43 | FT4: 87 | FU4: 79 | FV4: 68 | FW4: 18 | FX4: 29 | FY4: 25 | FZ4: 22 | GA4: 19 | GB4: 331.07712 | GC4: 281.43979 | GD4: 377.05161 | GE4: 318.5657 | GF4: 645.06561 | GG4: 588.06012 | GH4: 512.31824 | GI4: 137.55157 | GJ4: 221.52625 | GK4: 188.42328 | GL4: 164.76932 | GM4: 144.7178 | GN4: 5 | GO4: 3 | GP4: 5 | GQ4: 3 | GR4: 4 | GS4: 4 | GT4: 3 | GU4: 2 | GV4: 4 | GW4: 3 | GX4: 7 | GY4: 3 | GZ4: 36.786346 | HA4: 22.218931 | HB4: 36.965843 | HC4: 22.225515 | HD4: 29.65819 | HE4: 29.775198 | HF4: 22.602276 | HG4: 15.283509 | HH4: 30.555344 | HI4: 22.610792 | HJ4: 52.426601 | HK4: 22.85018 | HL4: 13129 | HM4: {"coordinates": [[[[-79.4341164165158, 43.6601538576501], [-79.4353691001115, 43.6598923457509], [-79.4355345634987, 43.6602810449928], [-79.4366816133018, 43.6629756534973], [-79.4367072790678, 43.6630357519051], [-79.4370626507975, 43.6638680774736], [-79.4374415152686, 43.6647239350082], [-79.437619772462, 43.6651298663564], [-79.4378108683775, 43.6655687229151], [-79.4379274723963, 43.6658597276168], [-79.4381883045272, 43.666436845523], [-79.4387032547807, 43.6676693880402], [-79.4389080670722, 43.6681596562064], [-79.4390391797812, 43.6684734047818], [-79.4392823330674, 43.6689922811114], [-79.4392928262882, 43.6690150782769], [-79.4366375850731, 43.6695294404342], [-79.4366240330887, 43.6695397843194], [-79.4362899137019, 43.6696116183585], [-79.4359561976587, 43.6696744411517], [-79.4352049985704, 43.6698360687182], [-79.4350410326748, 43.669876481065], [-79.434876302313, 43.6699124021174], [-79.4347115593747, 43.6699483140514], [-79.4345468272162, 43.6699842246643], [-79.4343816989007, 43.6700201450025], [-79.4342161744281, 43.6700560542729], [-79.4340506742101, 43.6700919648214], [-79.4338847679535, 43.6701233821477], [-79.43371887607, 43.6701547910105], [-79.4335526104873, 43.6701861985573], [-79.433383605043, 43.670217613885], [-79.4330122837254, 43.6702821709412], [-79.4329491132963, 43.670293871425], [-79.4293996638945, 43.6709812901789], [-79.4269763515161, 43.6714505290524], [-79.4229326759945, 43.6722217547361], [-79.4218563334857, 43.6724270647182], [-79.421547392978, 43.67163074861], [-79.4212300936466, 43.670783927772], [-79.4210940249322, 43.6704306305295], [-79.4209360822406, 43.6700204841861], [-79.4206443902847, 43.6692625144275], [-79.4202954370176, 43.6683475194401], [-79.4202051212973, 43.6681272118218], [-79.4199376847524, 43.6673998071041], [-79.4197631349061, 43.6669395091445], [-79.4197535965945, 43.6669143705725], [-79.4196273617375, 43.6665814573249], [-79.419595466155, 43.6664999010239], [-79.4194711366247, 43.6661820489254], [-79.4187943072621, 43.66445135939], [-79.4185781726048, 43.6639561858158], [-79.418419790637, 43.6635933372292], [-79.4188737174349, 43.6634815303566], [-79.4189382865409, 43.6634673987631], [-79.4202522190694, 43.6631798299245], [-79.4209181842069, 43.6630340655373], [-79.4216266845732, 43.6628811173064], [-79.4220632190889, 43.6627868831494], [-79.4232718412182, 43.6625185247646], [-79.424436276117, 43.6622586666639], [-79.4246485992226, 43.6622071482523], [-79.4256627280081, 43.6619934993497], [-79.4268616231796, 43.6617451422675], [-79.4280573176537, 43.6614891098502], [-79.4282085364553, 43.6614450720812], [-79.4294412531972, 43.6611593450438], [-79.4302399893338, 43.6609922390646], [-79.4304241304923, 43.6609537177223], [-79.4311353482623, 43.6607995040801], [-79.4316756453798, 43.6606697865598], [-79.4324384183623, 43.6604970629537], [-79.4329201264587, 43.6604005459212], [-79.4330379674577, 43.660374142541], [-79.4338386933626, 43.6601946898414], [-79.4341164165158, 43.6601538576501]]]], "type": "MultiPolygon"}
A5: 4 | B5: Junction-Wallace Emerson | C5: 171 | D5: 164 | E5: 159 | F5: 171 | G5: 161 | H5: 163 | I5: 186 | J5: 171 | K5: 182 | L5: 138 | M5: 230 | N5: 195 | O5: 200 | P5: 698.25861 | Q5: 667.03027 | R5: 697.90222 | S5: 652.87915 | T5: 655.40814 | U5: 743.34583 | V5: 685.34326 | W5: 734.67084 | X5: 541.36755 | Y5: 864.66168 | Z5: 709.19409 | AA5: 720.02014 | AB5: 21 | AC5: 18 | AD5: 14 | AE5: 18 | AF5: 34 | AG5: 24 | AH5: 47 | AI5: 35 | AJ5: 47 | AK5: 37 | AL5: 47 | AM5: 30 | AN5: 89.411163 | AO5: 75.512856 | AP5: 57.138191 | AQ5: 72.992699 | AR5: 136.71089 | AS5: 95.915596 | AT5: 188.3692 | AU5: 141.28285 | AV5: 184.3788 | AW5: 139.09775 | AX5: 170.93396 | AY5: 108.00302 | AZ5: 42 | BA5: 41 | BB5: 50 | BC5: 63 | BD5: 67 | BE5: 70 | BF5: 54 | BG5: 36 | BH5: 34 | BI5: 55 | BJ5: 41 | BK5: 43 | BL5: 178.82233 | BM5: 172.00151 | BN5: 204.06497 | BO5: 255.47446 | BP5: 269.40088 | BQ5: 279.75381 | BR5: 216.42419 | BS5: 145.3195 | BT5: 133.3804 | BU5: 206.76692 | BV5: 149.11259 | BW5: 154.80434 | BX5: 37 | BY5: 46 | BZ5: 41 | CA5: 51 | CB5: 91 | CC5: 103 | CD5: 110 | CE5: 76 | CF5: 56 | CG5: 82 | CH5: 77 | CI5: 64 | CJ5: 157.53395 | CK5: 192.97731 | CL5: 167.33328 | CM5: 206.81265 | CN5: 365.90268 | CO5: 411.63776 | CP5: 440.86411 | CQ5: 306.78561 | CR5: 219.68538 | CS5: 308.27069 | CT5: 280.04074 | CU5: 230.40645 | CV5: 1 | CW5: 3 | CY5: 1 | DA5: 1 | DH5: 4.2576747 | DI5: 12.585476 | DK5: 4.05515 | DM5: 3.9964831 | DT5: 26 | DU5: 30 | DV5: 27 | DW5: 30 | DX5: 22 | DY5: 32 | DZ5: 23 | EA5: 11 | EB5: 20 | EC5: 18 | ED5: 12 | EE5: 10 | EF5: 110.69954 | EG5: 125.85477 | EH5: 110.19508 | EI5: 121.6545 | EJ5: 88.459991 | EK5: 127.88746 | EL5: 92.180672 | EM5: 44.403179 | EN5: 78.459061 | EO5: 67.669174 | EP5: 43.642712 | EQ5: 36.001007 | ES5: 2 | ET5: 1 | EU5: 5 | EV5: 3 | EW5: 2 | EX5: 4 | EY5: 4 | EZ5: 3 | FA5: 2 | FC5: 1 | FE5: 8.3903179 | FF5: 4.0812993 | FG5: 20.275751 | FH5: 12.062726 | FI5: 7.9929662 | FJ5: 16.031422 | FK5: 16.146612 | FL5: 11.76886 | FM5: 7.5187969 | FO5: 3.6001008 | FP5: 74 | FQ5: 26 | FR5: 48 | FS5: 72 | FT5: 153 | FU5: 124 | FV5: 144 | FW5: 53 | FX5: 63 | FY5: 58 | FZ5: 71 | GA5: 56 | GB5: 315.0679 | GC5: 109.07413 | GD5: 195.90237 | GE5: 291.97079 | GF5: 615.19904 | GG5: 495.5639 | GH5: 577.13116 | GI5: 213.9426 | GJ5: 247.14606 | GK5: 218.04512 | GL5: 258.21939 | GM5: 201.60565 | GN5: 5 | GO5: 5 | GP5: 6 | GQ5: 6 | GR5: 9 | GS5: 4 | GT5: 9 | GU5: 8 | GV5: 8 | GW5: 9 | GX5: 13 | GY5: 9 | GZ5: 21.288372 | HA5: 20.975794 | HB5: 24.487797 | HC5: 24.3309 | HD5: 36.188179 | HE5: 15.985932 | HF5: 36.070698 | HG5: 32.293224 | HH5: 31.383625 | HI5: 33.834587 | HJ5: 47.279606 | HK5: 32.400906 | HL5: 27777 | HM5: {"coordinates": [[[[-79.4387032547807, 43.6676693880402], [-79.4384114999427, 43.6669710964218], [-79.4381883045272, 43.666436845523], [-79.4379274723963, 43.6658597276168], [-79.4378108683775, 43.6655687229151], [-79.437619772462, 43.6651298663564], [-79.4374415152686, 43.6647239350082], [-79.4370626507975, 43.6638680774736], [-79.4367072790678, 43.6630357519051], [-79.4366816133018, 43.6629756534973], [-79.4355345634987, 43.6602810449928], [-79.4353691001115, 43.6598923457509], [-79.4364447679856, 43.6596586616269], [-79.4376111378555, 43.6594350174206], [-79.4386741340942, 43.6592211168925], [-79.439178318039, 43.6591067367409], [-79.4397467162552, 43.6589989495707], [-79.4403922294487, 43.6588670945458], [-79.4407507641466, 43.6587903727589], [-79.4415820157031, 43.6586030144836], [-79.4417380288135, 43.6585700950554], [-79.4427372788029, 43.6583469979125], [-79.4440001421074, 43.6580982501004], [-79.4452218760467, 43.6578426902127], [-79.4452537078488, 43.6578360266963], [-79.4469374543217, 43.657485155409], [-79.4469920395517, 43.657473776085], [-79.4477753884458, 43.6573105190414], [-79.4480944583566, 43.6572431358505], [-79.4487996017186, 43.6570875420026], [-79.4489375371322, 43.657062454548], [-79.4496546361724, 43.6569257533754], [-79.4498738286949, 43.6568839661794], [-79.4513459464601, 43.6583825619187], [-79.4520346290929, 43.659082843338], [-79.4534456695035, 43.6605158106942], [-79.4535413346914, 43.6606148737671], [-79.4545500223812, 43.6616409646507], [-79.4560227950181, 43.6631390757961], [-79.4572819401957, 43.6644205440937], [-79.457820672448, 43.664968106548], [-79.4593211913491, 43.6664929642462], [-79.4600491411396, 43.6672345431539], [-79.4594744268686, 43.6672328926434], [-79.458562066425, 43.6672222578968], [-79.4580805775175, 43.6672166461599], [-79.4564324923647, 43.6671974599424], [-79.454969080173, 43.6671804564233], [-79.4531012644067, 43.6671509103036], [-79.4522129931858, 43.6671484897682], [-79.4522075862261, 43.6671482265959], [-79.4521164997512, 43.6671438949744], [-79.4520200197914, 43.6671393541143], [-79.4519235218653, 43.6671393229235], [-79.4518266574265, 43.6671347807635], [-79.451790362794, 43.6671345676263], [-79.4517301639919, 43.6671302483502], [-79.4516336795405, 43.6671302171594], [-79.4515368106102, 43.6671301762215], [-79.4514403270571, 43.667130143731], [-79.4513434329739, 43.6671301027932], [-79.4512473285099, 43.6671345715252], [-79.4511504479014, 43.6671345299375], [-79.4510539472803, 43.6671389895718], [-79.4509574502525, 43.6671389479841], [-79.4508609460382, 43.6671479166374], [-79.4507644499086, 43.6671478756995], [-79.4506679492876, 43.6671523340333], [-79.4505718169758, 43.667161294237], [-79.4504934084245, 43.6671657610173], [-79.4504753280328, 43.6671657532196], [-79.4503792091957, 43.6671747127715], [-79.4502830930536, 43.6671791717531], [-79.4501873479156, 43.6671850531637], [-79.4500915650485, 43.6671909969551], [-79.4499926686205, 43.667199180633], [-79.4497938714481, 43.6672140540781], [-79.4496784810533, 43.6672239227033], [-79.4495680260026, 43.6672328757485], [-79.4494571747948, 43.6672418281425], [-79.449346725134, 43.6672462793214], [-79.4492362584052, 43.6672552323633], [-79.4491261995115, 43.6672641841041], [-79.449018637036, 43.6672694832794], [-79.4491290804087, 43.667538726253], [-79.4491642737065, 43.667624255338], [-79.4492006240345, 43.6677052831218], [-79.4492373848926, 43.667786311446], [-79.4492748976405, 43.6678718317309], [-79.4493135790967, 43.6679528611298], [-79.4493526549132, 43.6680383902745], [-79.4493924907045, 43.6681194200984], [-79.4494335176618, 43.6682004504628], [-79.4494748994537, 43.6682859727567], [-79.4495174625302, 43.668367003546], [-79.4495604002041, 43.6684480257786], [-79.4496041292938, 43.6685290569988], [-79.449649013617, 43.6686100796625], [-79.4496942815208, 43.6686911119636], [-79.4497403291623, 43.6687721344085], [-79.4497871484566, 43.6688531671406], [-79.4498347349121, 43.6689341913161], [-79.4498827318977, 43.6690152244792], [-79.4499322524261, 43.6690962490857], [-79.4499817792426, 43.6691727731633], [-79.4500324918354, 43.6692538073039], [-79.4500839527248, 43.6693303318305], [-79.4501358052796, 43.6694113670579], [-79.4501888283392, 43.6694878920333], [-79.4502422322845, 43.6695689276979], [-79.4502964096793, 43.6696454622191], [-79.4503513793882, 43.6697219888454], [-79.4504070911055, 43.6698030241938], [-79.4504635987301, 43.6698795603659], [-79.4505201072531, 43.6699560964404], [-79.4512542491308, 43.6708869335857], [-79.4513825276551, 43.6710495793192], [-79.4511036501667, 43.6711061953486], [-79.4494702120445, 43.6713747960406], [-79.4494227109289, 43.6713826061845], [-79.448307057245, 43.6715660494073], [-79.4474937719941, 43.6717047042083], [-79.4472364450894, 43.671740878222], [-79.4460516983837, 43.6719460326082], [-79.4456183169546, 43.6720186031891], [-79.4451054840303, 43.672102557383], [-79.4447543828914, 43.6721739120853], [-79.4445522421895, 43.672217272738], [-79.44376949337, 43.67238516096], [-79.4426276043882, 43.6726308074536], [-79.442114897228, 43.6727411119619], [-79.441865231156, 43.672798791331], [-79.4409992848666, 43.6729988526497], [-79.4398105622174, 43.6732642312474], [-79.4395288253914, 43.6733310610702], [-79.4383989379018, 43.6737017808385], [-79.4383505824884, 43.6737169853376], [-79.4380946461757, 43.6737974708131], [-79.4376559386354, 43.6739143946261], [-79.4374745939323, 43.673949527083], [-79.4373311096253, 43.6739727615859], [-79.4371442348933, 43.6739828305176], [-79.4359311867646, 43.6741507150998], [-79.4346540483319, 43.6742992255437], [-79.4344846817648, 43.673888371437], [-79.433341416564, 43.6711147072739], [-79.4331800575794, 43.6707232354347], [-79.4330954964668, 43.6705009248426], [-79.4330122837254, 43.6702821709412], [-79.433383605043, 43.670217613885], [-79.4335526104873, 43.6701861985573], [-79.43371887607, 43.6701547910105], [-79.4338847679535, 43.6701233821477], [-79.4340506742101, 43.6700919648214], [-79.4342161744281, 43.6700560542729], [-79.4343816989007, 43.6700201450025], [-79.4345468272162, 43.6699842246643], [-79.4347115593747, 43.6699483140514], [-79.434876302313, 43.6699124021174], [-79.4350410326748, 43.669876481065], [-79.4352049985704, 43.6698360687182], [-79.4359561976587, 43.6696744411517], [-79.4362899137019, 43.6696116183585], [-79.4366240330887, 43.6695397843194], [-79.4366375850731, 43.6695294404342], [-79.4392928262882, 43.6690150782769], [-79.4392823330674, 43.6689922811114], [-79.4390391797812, 43.6684734047818], [-79.4389080670722, 43.6681596562064], [-79.4387032547807, 43.6676693880402]]]], "type": "MultiPolygon"}
A6: 5 | B6: Yonge-Bay Corridor | C6: 170 | D6: 387 | E6: 521 | F6: 481 | G6: 602 | H6: 576 | I6: 660 | J6: 377 | K6: 325 | L6: 441 | M6: 543 | N6: 554 | O6: 560 | P6: 3750 | Q6: 4761.9048 | R6: 4119.5615 | S6: 4949.8438 | T6: 4541.1543 | U6: 5015.1978 | V6: 2785.1655 | W6: 2345.385 | X6: 3042.2185 | Y6: 3523.686 | Z6: 3416.8003 | AA6: 3361.1428 | AB6: 13 | AC6: 20 | AD6: 20 | AE6: 14 | AF6: 32 | AG6: 37 | AH6: 16 | AI6: 18 | AJ6: 30 | AK6: 48 | AL6: 38 | AM6: 27 | AN6: 125.96899 | AO6: 182.79865 | AP6: 171.29153 | AQ6: 115.11265 | AR6: 252.28635 | AS6: 281.15503 | AT6: 118.20331 | AU6: 129.89824 | AV6: 206.95364 | AW6: 311.48605 | AX6: 234.36536 | AY6: 162.0551 | AZ6: 220 | BA6: 154 | BB6: 202 | BC6: 214 | BD6: 263 | BE6: 220 | BF6: 172 | BG6: 167 | BH6: 229 | BI6: 228 | BJ6: 192 | BK6: 137 | BL6: 2131.783 | BM6: 1407.5496 | BN6: 1730.0446 | BO6: 1759.579 | BP6: 2073.4785 | BQ6: 1671.7325 | BR6: 1270.6855 | BS6: 1205.1671 | BT6: 1579.7461 | BU6: 1479.5587 | BV6: 1184.1619 | BW6: 822.2796 | BX6: 69 | BY6: 115 | BZ6: 60 | CA6: 125 | CB6: 99 | CC6: 119 | CD6: 148 | CE6: 112 | CF6: 123 | CG6: 108 | CH6: 95 | CI6: 92 | CJ6: 668.60468 | CK6: 1051.0922 | CL6: 513.87463 | CM6: 1027.7915 | CN6: 780.51086 | CO6: 904.25531 | CP6: 1093.3806 | CQ6: 808.25574 | CR6: 848.50995 | CS6: 700.84363 | CT6: 585.91339 | CU6: 552.18774 | CV6: 1 | CW6: 2 | CZ6: 1 | DA6: 2 | DC6: 1 | DD6: 1 | DE6: 1 | DF6: 1 | DG6: 2 | DH6: 9.6899223 | DI6: 18.279865 | DL6: 7.8839483 | DM6: 15.197568 | DO6: 7.2165694 | DP6: 6.8984547 | DQ6: 6.4892926 | DR6: 6.1675096 | DS6: 12.004082 | DT6: 72 | DU6: 52 | DV6: 73 | DW6: 86 | DX6: 90 | DY6: 63 | DZ6: 55 | EA6: 50 | EB6: 55 | EC6: 60 | ED6: 65 | EE6: 50 | EF6: 697.67444 | EG6: 475.27649 | EH6: 625.21411 | EI6: 707.12054 | EJ6: 709.55536 | EK6: 478.72342 | EL6: 406.32388 | EM6: 360.82846 | EN6: 379.41501 | EO6: 389.35757 | EP6: 400.88812 | EQ6: 300.10202 | ER6: 1 | ES6: 3 | EU6: 3 | EV6: 4 | EW6: 4 | EX6: 2 | EZ6: 1 | FA6: 2 | FB6: 1 | FC6: 2 | FD6: 9.6899223 | FE6: 27.419798 | FG6: 24.666996 | FH6: 31.535793 | FI6: 30.395136 | FJ6: 14.775414 | FL6: 6.8984547 | FM6: 12.978585 | FN6: 6.1675096 | FO6: 12.004082 | FP6: 120 | FQ6: 102 | FR6: 77 | FS6: 86 | FT6: 112 | FU6: 171 | FV6: 135 | FW6: 63 | FX6: 107 | FY6: 76 | FZ6: 77 | GA6: 67 | GB6: 1162.7906 | GC6: 932.27307 | GD6: 659.47241 | GE6: 707.12054 | GF6: 883.0022 | GG6: 1299.3921 | GH6: 997.34045 | GI6: 454.64386 | GJ6: 738.13464 | GK6: 493.18625 | GL6: 474.89822 | GM6: 402.13672 | GN6: 37 | GO6: 30 | GP6: 27 | GQ6: 35 | GR6: 44 | GS6: 63 | GT6: 35 | GU6: 26 | GV6: 51 | GW6: 52 | GX6: 48 | GY6: 35 | GZ6: 358.52713 | HA6: 274.19797 | HB6: 231.24358 | HC6: 287.78162 | HD6: 346.89374 | HE6: 478.72342 | HF6: 258.56973 | HG6: 187.6308 | HH6: 351.8212 | HI6: 337.44321 | HJ6: 296.04047 | HK6: 210.07143 | HL6: 16661 | HM6: {"coordinates": [[[[-79.3840431592607, 43.6449736752406], [-79.3850247331003, 43.644784189146], [-79.3855651128628, 43.6460625747369], [-79.3861138146182, 43.6474036687174], [-79.386372697405, 43.6480179011607], [-79.3866245688409, 43.6486468331157], [-79.3868843759941, 43.6492632342524], [-79.3871409743652, 43.6499149972361], [-79.3872928049195, 43.65026704634], [-79.3874340218788, 43.6505945017637], [-79.3875195693416, 43.6506815031586], [-79.3866318703476, 43.6508614282289], [-79.3869995220473, 43.6517645027111], [-79.3872484479074, 43.6523227783319], [-79.3875547967755, 43.6530431440201], [-79.3875852550535, 43.6531164719093], [-79.3879417496774, 43.653975181957], [-79.3883177575059, 43.6547987692274], [-79.388324091527, 43.6548126909804], [-79.38860240667, 43.6554741128636], [-79.3886916381238, 43.6556861815823], [-79.3889710725676, 43.6563565316139], [-79.3889750476128, 43.6563660588636], [-79.3893311155369, 43.6571405206203], [-79.389492612862, 43.6575381492737], [-79.3896511259838, 43.657928447582], [-79.3899392354583, 43.6585993353958], [-79.3899871506973, 43.6587098008694], [-79.3903102944679, 43.659454829365], [-79.3904978402414, 43.6598674232397], [-79.3874287290052, 43.660523449383], [-79.3866856372123, 43.660670030914], [-79.3858581810378, 43.6608242468384], [-79.3837092635544, 43.6612608070319], [-79.3831136167407, 43.6613804028409], [-79.3827994031223, 43.6605919421357], [-79.3824939301116, 43.6599214151771], [-79.3821210807597, 43.6591045550426], [-79.3819385898063, 43.6586994050757], [-79.3819284559116, 43.6586766117913], [-79.3815904602944, 43.6579163956871], [-79.381373197353, 43.6574245341138], [-79.3812290105634, 43.6570465166225], [-79.3809296371135, 43.6563373575235], [-79.3806781187154, 43.6557826574483], [-79.3799772154015, 43.654071387593], [-79.3792621672151, 43.6524485263358], [-79.3789879106606, 43.6517005926152], [-79.3787427792842, 43.6510640715951], [-79.3784733044619, 43.6504160656692], [-79.3779215547228, 43.6491573300215], [-79.3776514941989, 43.6485320681666], [-79.377373572518, 43.6478548758168], [-79.3769775493267, 43.6468933753162], [-79.3770276923875, 43.646819050486], [-79.3771055269153, 43.6467574121789], [-79.3775461703251, 43.646478508839], [-79.3776590840647, 43.6464295100644], [-79.3777924596299, 43.6463508632391], [-79.377895744328, 43.6463063898956], [-79.377926154097, 43.6462924609705], [-79.3780367474883, 43.6462380037046], [-79.3781869655667, 43.6461914742169], [-79.3784725408939, 43.646110091079], [-79.3791382059941, 43.6459956424014], [-79.3824743010243, 43.6453008390508], [-79.3825381155455, 43.6452868981917], [-79.3834299396033, 43.6450920319972], [-79.3839961019129, 43.6449827551129], [-79.3840431592607, 43.6449736752406]]]], "type": "MultiPolygon"}
A7: 6 | B7: Bay-Cloverhill | C7: 169 | D7: 107 | E7: 101 | F7: 122 | G7: 155 | H7: 136 | I7: 166 | J7: 106 | K7: 146 | L7: 122 | M7: 142 | N7: 122 | O7: 145 | P7: 764.06738 | Q7: 691.92297 | R7: 794.16742 | S7: 959.03973 | T7: 800.51801 | U7: 935.94946 | V7: 578.82379 | W7: 778.25159 | X7: 610.24408 | Y7: 656.82965 | Z7: 528.06995 | AA7: 601.93451 | AB7: 7 | AC7: 5 | AD7: 8 | AE7: 7 | AF7: 19 | AG7: 13 | AH7: 9 | AI7: 24 | AJ7: 15 | AK7: 16 | AL7: 8 | AM7: 4 | AN7: 49.985718 | AO7: 34.253613 | AP7: 52.076553 | AQ7: 43.31147 | AR7: 111.83707 | AS7: 73.297249 | AT7: 49.145416 | AU7: 127.93177 | AV7: 75.030014 | AW7: 74.008972 | AX7: 34.627537 | AY7: 16.605089 | AZ7: 76 | BA7: 86 | BB7: 97 | BC7: 100 | BD7: 100 | BE7: 66 | BF7: 59 | BG7: 59 | BH7: 67 | BI7: 56 | BJ7: 44 | BK7: 57 | BL7: 542.70209 | BM7: 589.16217 | BN7: 631.42822 | BO7: 618.73529 | BP7: 588.61615 | BQ7: 372.12448 | BR7: 322.17551 | BS7: 314.49893 | BT7: 335.13406 | BU7: 259.0314 | BV7: 190.45146 | BW7: 236.62253 | BX7: 26 | BY7: 45 | BZ7: 59 | CA7: 54 | CB7: 72 | CC7: 82 | CD7: 80 | CE7: 38 | CF7: 43 | CG7: 63 | CH7: 70 | CI7: 69 | CJ7: 185.66124 | CK7: 308.28253 | CL7: 384.06458 | CM7: 334.11707 | CN7: 423.80365 | CO7: 462.33649 | CP7: 436.84814 | CQ7: 202.55864 | CR7: 215.08603 | CS7: 291.41034 | CT7: 302.99097 | CU7: 286.43781 | DA7: 1 | DM7: 5.6382499 | DT7: 12 | DU7: 15 | DV7: 19 | DW7: 22 | DX7: 29 | DY7: 36 | DZ7: 18 | EA7: 21 | EB7: 20 | EC7: 20 | ED7: 18 | EE7: 18 | EF7: 85.689804 | EG7: 102.76084 | EH7: 123.68181 | EI7: 136.12177 | EJ7: 170.69868 | EK7: 202.97699 | EL7: 98.290833 | EM7: 111.9403 | EN7: 100.04002 | EO7: 92.511215 | EP7: 77.911957 | EQ7: 74.7229 | EV7: 1 | EZ7: 1 | FA7: 1 | FH7: 5.8861618 | FL7: 5.0020008 | FM7: 4.6255608 | FP7: 38 | FQ7: 24 | FR7: 25 | FS7: 18 | FT7: 32 | FU7: 33 | FV7: 35 | FW7: 21 | FX7: 26 | FY7: 40 | FZ7: 61 | GA7: 35 | GB7: 271.35104 | GC7: 164.41734 | GD7: 162.73923 | GE7: 111.37235 | GF7: 188.35718 | GG7: 186.06224 | GH7: 191.12106 | GI7: 111.9403 | GJ7: 130.05202 | GK7: 185.02243 | GL7: 264.03497 | GM7: 145.29453 | GN7: 16 | GO7: 13 | GP7: 13 | GQ7: 14 | GR7: 9 | GS7: 10 | GT7: 7 | GU7: 10 | GV7: 9 | GW7: 13 | GX7: 25 | GY7: 21 | GZ7: 114.25307 | HA7: 89.059395 | HB7: 84.624397 | HC7: 86.62294 | HD7: 52.975456 | HE7: 56.3825 | HF7: 38.224213 | HG7: 53.304905 | HH7: 45.018005 | HI7: 60.13229 | HJ7: 108.21105 | HK7: 87.17672 | HL7: 24089 | HM7: {"coordinates": [[[[-79.3874287290052, 43.660523449383], [-79.3904978402414, 43.6598674232397], [-79.390633581969, 43.6601660741664], [-79.3906426459702, 43.6601860301437], [-79.3906789909083, 43.6602659963113], [-79.3906938454498, 43.6602788204449], [-79.3907069842092, 43.6603013356213], [-79.3907201193753, 43.6603193510058], [-79.390734418758, 43.6603373676847], [-79.3907495203362, 43.6603508832772], [-79.3907649731557, 43.6603689018962], [-79.3907812155944, 43.6603824194313], [-79.3907978344271, 43.660400437391], [-79.3908156318495, 43.660418457295], [-79.3908334355601, 43.6604319761186], [-79.3908520100253, 43.6604454955892], [-79.3908713435668, 43.6604635167793], [-79.3908910696722, 43.6604770381924], [-79.3909115898882, 43.6604905589525], [-79.3909324829051, 43.6605040816592], [-79.3909541547613, 43.6605176037131], [-79.3909762254695, 43.6605311264137], [-79.3909986546055, 43.660544650411], [-79.3910214888817, 43.6605536739895], [-79.3910451091838, 43.6605671979818], [-79.391068724096, 43.6605762222067], [-79.3910931331189, 43.6605852464303], [-79.3911175178873, 43.6605942713025], [-79.3911426877832, 43.6606077972353], [-79.3911676411852, 43.6606175870114], [-79.3911997550583, 43.6606234508682], [-79.3912193571961, 43.660630373377], [-79.3913010445982, 43.6606619470772], [-79.3913521560429, 43.6606799980968], [-79.3914024787668, 43.6607025488661], [-79.3914527934058, 43.6607296006798], [-79.3915023606466, 43.6607521611786], [-79.3915515299337, 43.6607747106211], [-79.3916002707244, 43.6608017611025], [-79.3916482748965, 43.6608243183248], [-79.3916962709838, 43.6608513681341], [-79.3917431010579, 43.6608784166313], [-79.3918160352758, 43.6609316473053], [-79.3919267472447, 43.6610124313218], [-79.3920522212286, 43.6611304945744], [-79.3921372225157, 43.6612228655479], [-79.3922179711783, 43.6613365034147], [-79.3922814407464, 43.6614545978737], [-79.3923012620731, 43.6614914493801], [-79.3924084930703, 43.6617307789127], [-79.3924965998334, 43.6619049923592], [-79.3929126123364, 43.6624326816712], [-79.3929524103984, 43.6624831718129], [-79.3931092149245, 43.6627736754868], [-79.3932123073832, 43.6630774223953], [-79.3935914997393, 43.6640877898731], [-79.3938607005755, 43.6648141059655], [-79.3938684099172, 43.6648366161919], [-79.393875338623, 43.6648591257601], [-79.3938811147903, 43.66488163467], [-79.3938861130165, 43.6649086436613], [-79.3938907231706, 43.6649311519028], [-79.3938945526886, 43.6649536588362], [-79.3938972170917, 43.6649761644615], [-79.3938991107404, 43.6649986603309], [-79.3939006217067, 43.6650211737374], [-79.3939006064353, 43.6650298333874], [-79.3939005812825, 43.6650436682902], [-79.3939005417566, 43.6650661712825], [-79.393898944552, 43.6650931736924], [-79.393896958377, 43.6651156753664], [-79.3938942158204, 43.6651381763822], [-79.3938903000641, 43.6651651768102], [-79.39388560996, 43.6651876758579], [-79.3938805228005, 43.6652101742474], [-79.3938746568017, 43.6652326726284], [-79.3938676481459, 43.6652551697014], [-79.3938598579557, 43.6652776648164], [-79.393851299706, 43.6653001605728], [-79.3938419608203, 43.6653226550212], [-79.3938335696573, 43.6653420367863], [-79.3938322248793, 43.6653451494611], [-79.3938213355014, 43.6653676432428], [-79.3938096726741, 43.665385634363], [-79.3937991929279, 43.6654081281295], [-79.3937969776825, 43.6654125554009], [-79.3937879190711, 43.6654306212378], [-79.3937758645783, 43.6654531136877], [-79.3937630483142, 43.6654711132301], [-79.3937494505157, 43.6654891036696], [-79.3937354619501, 43.6655115941482], [-79.3937203154561, 43.665529582626], [-79.3937047763984, 43.6655520620424], [-79.3936888600481, 43.6655700589559], [-79.3936714066805, 43.6655880461166], [-79.3936539290583, 43.6656060319722], [-79.3936356869698, 43.665628518508], [-79.3936170630974, 43.6656420030175], [-79.3935972660251, 43.6656599875573], [-79.393577084474, 43.6656779707921], [-79.3935561348632, 43.6656959540215], [-79.3935348079601, 43.6657094365664], [-79.3935130651369, 43.6657274184867], [-79.3934905722205, 43.6657408997248], [-79.3934676831471, 43.66575438031], [-79.3934440305057, 43.6657723615671], [-79.3934199763173, 43.6657858408457], [-79.3933955367517, 43.6657993201212], [-79.3933934391855, 43.665800443015], [-79.3933567600741, 43.6658360721372], [-79.3933240416348, 43.6658683657018], [-79.3932823939416, 43.6659157455075], [-79.3932496764007, 43.6659545021503], [-79.3932139450119, 43.6660148048687], [-79.3931960685378, 43.6660686613137], [-79.393181125063, 43.6661182172063], [-79.3931721311304, 43.6661699213589], [-79.3931720709433, 43.6662108683752], [-79.3931719900949, 43.6662561360026], [-79.3931539743819, 43.6663810938936], [-79.3935294396279, 43.6672736569888], [-79.3941446526469, 43.6687288440434], [-79.3910298620785, 43.6693669107913], [-79.3905883796422, 43.6694560611122], [-79.3895108181196, 43.6696776458707], [-79.3880216422455, 43.6699829978845], [-79.3874108660058, 43.6701080929171], [-79.3867913042425, 43.6702349758692], [-79.3865607255737, 43.6696956577918], [-79.3864281935266, 43.6693768966735], [-79.3861635112163, 43.6687508609102], [-79.3861162903751, 43.6686394398732], [-79.3858592706942, 43.6680044187969], [-79.3856956165141, 43.6675708947892], [-79.3853434068541, 43.6667036144945], [-79.3853298018691, 43.6666788741592], [-79.3852620221843, 43.6665557129757], [-79.3850549865625, 43.6660722502688], [-79.3850435662802, 43.666046206784], [-79.384957094451, 43.6658490003521], [-79.3845991212002, 43.6649458680006], [-79.3841608996484, 43.6639125384628], [-79.3841405222645, 43.6638637488646], [-79.3837920846304, 43.663029852542], [-79.3837368660882, 43.6629046511281], [-79.3834250348019, 43.6621446737682], [-79.3833897193331, 43.6620630854449], [-79.3831136167407, 43.6613804028409], [-79.3837092635544, 43.6612608070319], [-79.3858581810378, 43.6608242468384], [-79.3866856372123, 43.660670030914], [-79.3874287290052, 43.660523449383]]]], "type": "MultiPolygon"}
A8: 7 | B8: Bendale-Glen Andrew | C8: 156 | D8: 137 | E8: 149 | F8: 174 | G8: 168 | H8: 183 | I8: 204 | J8: 134 | K8: 129 | L8: 166 | M8: 242 | N8: 196 | O8: 180 | P8: 734.93909 | Q8: 787.69293 | R8: 875.20746 | S8: 838.40704 | T8: 905.04449 | U8: 1002.1615 | V8: 660.55408 | W8: 640.86639 | X8: 820.03656 | Y8: 1172.3102 | Z8: 938.06836 | AA8: 871.75513 | AB8: 38 | AC8: 39 | AD8: 42 | AE8: 26 | AF8: 39 | AG8: 38 | AH8: 48 | AI8: 77 | AJ8: 84 | AK8: 152 | AL8: 128 | AM8: 96 | AN8: 203.85173 | AO8: 206.17467 | AP8: 211.25697 | AQ8: 129.75346 | AR8: 192.87834 | AS8: 186.67714 | AT8: 236.61638 | AU8: 382.53265 | AV8: 414.95825 | AW8: 736.32709 | AX8: 612.61609 | AY8: 464.93607 | AZ8: 10 | BA8: 7 | BB8: 4 | BC8: 23 | BD8: 2 | BE8: 3 | BF8: 1 | BG8: 4 | BH8: 6 | BI8: 10 | BJ8: 14 | BK8: 12 | BL8: 53.645191 | BM8: 37.005711 | BN8: 20.119713 | BO8: 114.78191 | BP8: 9.8911972 | BQ8: 14.73767 | BR8: 4.9295082 | BS8: 19.871826 | BT8: 29.639875 | BU8: 48.44257 | BV8: 67.004883 | BW8: 58.117008 | BX8: 71 | BY8: 33 | BZ8: 30 | CA8: 27 | CB8: 33 | CC8: 30 | CD8: 20 | CE8: 19 | CF8: 24 | CG8: 28 | CH8: 23 | CI8: 30 | CJ8: 380.88086 | CK8: 174.45549 | CL8: 150.89784 | CM8: 134.74399 | CN8: 163.20474 | CO8: 147.37669 | CP8: 98.590164 | CQ8: 94.391174 | CR8: 118.5595 | CS8: 135.63921 | CT8: 110.07944 | CU8: 145.29253 | CX8: 2 | DA8: 1 | DB8: 1 | DD8: 2 | DF8: 2 | DG8: 2 | DJ8: 10.059856 | DM8: 4.9125566 | DN8: 4.9295082 | DP8: 9.8799582 | DR8: 9.5721264 | DS8: 9.6861677 | DT8: 53 | DU8: 55 | DV8: 49 | DW8: 67 | DX8: 44 | DY8: 35 | DZ8: 19 | EA8: 49 | EB8: 54 | EC8: 52 | ED8: 56 | EE8: 46 | EF8: 284.31952 | EG8: 290.75916 | EH8: 246.46648 | EI8: 334.36472 | EJ8: 217.60632 | EK8: 171.93948 | EL8: 93.660652 | EM8: 243.42987 | EN8: 266.75888 | EO8: 251.90137 | EP8: 268.01953 | EQ8: 222.78186 | ER8: 1 | ES8: 1 | ET8: 3 | EU8: 5 | EV8: 1 | EW8: 3 | EX8: 7 | EY8: 5 | EZ8: 7 | FA8: 1 | FB8: 3 | FC8: 3 | FD8: 5.3645191 | FE8: 5.28653 | FF8: 15.089785 | FG8: 24.952591 | FH8: 4.9455986 | FI8: 14.73767 | FJ8: 34.506557 | FK8: 24.839783 | FL8: 34.579853 | FM8: 4.8442574 | FN8: 14.358189 | FO8: 14.529252 | FP8: 84 | FQ8: 64 | FR8: 45 | FS8: 64 | FT8: 53 | FU8: 50 | FV8: 44 | FW8: 41 | FX8: 69 | FY8: 77 | FZ8: 71 | GA8: 60 | GB8: 450.6196 | GC8: 338.33792 | GD8: 226.34676 | GE8: 319.39316 | GF8: 262.11673 | GG8: 245.62782 | GH8: 216.89835 | GI8: 203.68622 | GJ8: 340.85858 | GK8: 373.00781 | GL8: 339.81049 | GM8: 290.58505 | GN8: 6 | GO8: 8 | GP8: 8 | GQ8: 17 | GR8: 13 | GS8: 8 | GT8: 4 | GU8: 7 | GV8: 13 | GW8: 20 | GX8: 15 | GY8: 17 | GZ8: 32.187115 | HA8: 42.29224 | HB8: 40.239426 | HC8: 84.838806 | HD8: 64.292778 | HE8: 39.300453 | HF8: 19.718033 | HG8: 34.775696 | HH8: 64.219727 | HI8: 96.885139 | HJ8: 71.790947 | HK8: 82.332428 | HL8: 20648 | HM8: {"coordinates": [[[[-79.2639217033978, 43.751762053982], [-79.2650557024765, 43.7515303051844], [-79.2651341245025, 43.7517194918767], [-79.265199264937, 43.7519356542643], [-79.2653164654372, 43.7523319480007], [-79.2654023093441, 43.752611161398], [-79.2655119846571, 43.7529444303009], [-79.2655787743985, 43.7531335930566], [-79.2656540711856, 43.7533317732724], [-79.2657147227386, 43.7535029208052], [-79.2657855405257, 43.7536560779041], [-79.2659078380669, 43.7539443660296], [-79.2663811657799, 43.7551874813433], [-79.2666687147058, 43.7559081647129], [-79.2671828609671, 43.7572683833291], [-79.2674502921221, 43.7579620103271], [-79.2678370204451, 43.7589169046187], [-79.2683126631167, 43.7601599886503], [-79.2689252198174, 43.7617363822778], [-79.2692742880688, 43.7626011737125], [-79.2696908332728, 43.7636821381284], [-79.2701850180701, 43.7649612908849], [-79.2705610456616, 43.7658891677029], [-79.2707999588996, 43.7665377409447], [-79.2708561179779, 43.7666728715135], [-79.2708874934358, 43.7667899496111], [-79.2709249738444, 43.7669340437199], [-79.2709577991832, 43.7670781277508], [-79.2710202401803, 43.7673933030196], [-79.2710771628266, 43.7677354613677], [-79.2711136461052, 43.7679335607866], [-79.2711796372443, 43.7681454278531], [-79.2712087579309, 43.7683194963315], [-79.2712532065711, 43.7685070341172], [-79.2712964083498, 43.7686793046219], [-79.2713462001693, 43.7688108034342], [-79.2713844890617, 43.7689423421771], [-79.271457270566, 43.7691429617023], [-79.2716536072528, 43.7696659535089], [-79.2718958343759, 43.7702699473561], [-79.2719744630144, 43.770455726918], [-79.2720395962624, 43.7706139983347], [-79.2723254626437, 43.7713176574732], [-79.2726244282585, 43.7720540532757], [-79.2729222071987, 43.7727548997304], [-79.2729895215562, 43.7729745991713], [-79.2733078296957, 43.7736854318904], [-79.2736854257456, 43.7746164594054], [-79.2740145873303, 43.7754479453638], [-79.2742842328325, 43.7761034382957], [-79.2745211050982, 43.7766655972234], [-79.2746561021225, 43.7769532789373], [-79.2747113170714, 43.7771196304874], [-79.2747156649174, 43.777132779888], [-79.2747758412617, 43.7772817065553], [-79.2747796698814, 43.7772910479039], [-79.2746897763692, 43.7773112399225], [-79.2717896274582, 43.7779447304752], [-79.269059123592, 43.7785112430173], [-79.2679949379839, 43.7787155294053], [-79.2660371694166, 43.7790973098757], [-79.2648771524323, 43.7793217136071], [-79.2647697480603, 43.7793425016449], [-79.2647958207632, 43.7794067959237], [-79.263921145544, 43.7795066517175], [-79.2637109092248, 43.779547326117], [-79.2603478602445, 43.7802164365112], [-79.2579690405238, 43.7806594377407], [-79.2549830575874, 43.7812311481598], [-79.2549779084442, 43.7812171403026], [-79.2549489018437, 43.7811405769731], [-79.2549189870464, 43.7810641834719], [-79.2549059515933, 43.7810317242953], [-79.2548883643767, 43.7809879585025], [-79.2548569952069, 43.7809119396828], [-79.2548359665444, 43.7808621718813], [-79.2548248921136, 43.7808359914612], [-79.2548056987093, 43.7807934377149], [-79.2548023363152, 43.7807860134577], [-79.2547918700438, 43.7807602928454], [-79.2547581625594, 43.7806847906528], [-79.2547236600659, 43.7806093765715], [-79.2546884371237, 43.7805342315555], [-79.2546523428155, 43.7804592648047], [-79.2546156268733, 43.7803845029115], [-79.2545780162089, 43.7803098751813], [-79.2545396958756, 43.780235542463], [-79.2545006308388, 43.7801613698525], [-79.254460656707, 43.7800874831756], [-79.2542285212577, 43.7796155759225], [-79.2542214398384, 43.7795973966071], [-79.25403463787, 43.7791171250992], [-79.2538519160496, 43.7786603277527], [-79.2535885201268, 43.7780018033708], [-79.253564854909, 43.7779411475671], [-79.2535626315787, 43.7779380640865], [-79.2531342124433, 43.7768371171261], [-79.2529269109201, 43.7763161319584], [-79.2525906876789, 43.7754470353294], [-79.2524001100914, 43.7749610373725], [-79.2522431142241, 43.774582702035], [-79.2521940203955, 43.7744718272667], [-79.2518753152007, 43.7736580788048], [-79.2517533922571, 43.7733220432873], [-79.2516891699008, 43.7731421682967], [-79.2516409770824, 43.7729851470542], [-79.2516089027352, 43.7728712750975], [-79.251580646228, 43.7727506256843], [-79.2515558401497, 43.7726303970113], [-79.2515337532718, 43.7725167630884], [-79.2515127273043, 43.7724017005835], [-79.2515016313139, 43.7721506338871], [-79.251428728537, 43.7719434482077], [-79.2513354070537, 43.7716102027426], [-79.251068227427, 43.770889526876], [-79.2508137266221, 43.7701921024655], [-79.2507658041967, 43.7700607604304], [-79.2504033986582, 43.7690968447392], [-79.250214300596, 43.7686463638677], [-79.2497403189094, 43.7674391514281], [-79.2489615109991, 43.7654301459722], [-79.2486288378999, 43.7646013155575], [-79.2482104080304, 43.7634842568875], [-79.2476119216421, 43.7619887409435], [-79.2472440489568, 43.7610428035761], [-79.2468865266602, 43.7601663228885], [-79.2468545053136, 43.7600878153988], [-79.2466732369674, 43.7596283540307], [-79.2462251186761, 43.7583942334266], [-79.2459543502798, 43.7576784779964], [-79.2459150004771, 43.757574454015], [-79.2459111772473, 43.7575654359476], [-79.245823545693, 43.7573582224563], [-79.2457544032639, 43.7571870548056], [-79.2457060712067, 43.7570519300607], [-79.2456400342535, 43.7568807693198], [-79.245595627834, 43.7567366509956], [-79.24555891818, 43.75661055253], [-79.2455175795072, 43.7564754427043], [-79.2455164799693, 43.7564709397519], [-79.2454845834885, 43.7561853597429], [-79.2454750334987, 43.756003938277], [-79.2454754619951, 43.7559057535992], [-79.2454758473724, 43.7558086581754], [-79.2454584838363, 43.7557392476624], [-79.2454398096581, 43.755627177171], [-79.2454259747044, 43.7555571344672], [-79.2467621620957, 43.7552720652867], [-79.2484913211013, 43.7549248368571], [-79.250884620766, 43.7544350034751], [-79.2509369700892, 43.7544240195297], [-79.2515643139578, 43.7542924547023], [-79.2553704021548, 43.7535355538975], [-79.2559172704486, 43.7534197067286], [-79.2566478693709, 43.753251322518], [-79.2568455966497, 43.7532056475167], [-79.2580789547887, 43.7529832085751], [-79.2585264703104, 43.7528671299847], [-79.2601389588219, 43.7525464373026], [-79.2616450984817, 43.7522255002184], [-79.2624629336995, 43.7520741466117], [-79.2639217033978, 43.751762053982]]]], "type": "MultiPolygon"}
